ERROR: Exception:
Traceback (most recent call last):
  File "/usr/lib/python3.11/pkgutil.py", line 418, in get_importer
    importer = sys.path_importer_cache[path_item]
               ~~~~~~~~~~~~~~~~~~~~~~~^^^^^^^^^^^
KeyError: ''

During handling of the above exception, another exception occurred:

Traceback (most recent call last):
  File "/tmp/tmpnlz8l5dq/pip-23.0.1-py3-none-any.whl/pip/_internal/cli/base_command.py", line 160, in exc_logging_wrapper
    status = run_func(*args)
             ^^^^^^^^^^^^^^^
  File "/tmp/tmpnlz8l5dq/pip-23.0.1-py3-none-any.whl/pip/_internal/cli/req_command.py", line 247, in wrapper
    return func(self, options, args)
           ^^^^^^^^^^^^^^^^^^^^^^^^^
  File "/tmp/tmpnlz8l5dq/pip-23.0.1-py3-none-any.whl/pip/_internal/commands/install.py", line 345, in run
    session = self.get_default_session(options)
              ^^^^^^^^^^^^^^^^^^^^^^^^^^^^^^^^^
  File "/tmp/tmpnlz8l5dq/pip-23.0.1-py3-none-any.whl/pip/_internal/cli/req_command.py", line 98, in get_default_session
    self._session = self.enter_context(self._build_session(options))
                                       ^^^^^^^^^^^^^^^^^^^^^^^^^^^^
  File "/tmp/tmpnlz8l5dq/pip-23.0.1-py3-none-any.whl/pip/_internal/cli/req_command.py", line 125, in _build_session
    session = PipSession(
              ^^^^^^^^^^^
  File "/tmp/tmpnlz8l5dq/pip-23.0.1-py3-none-any.whl/pip/_internal/network/session.py", line 343, in __init__
    self.headers["User-Agent"] = user_agent()
                                 ^^^^^^^^^^^^
  File "/tmp/tmpnlz8l5dq/pip-23.0.1-py3-none-any.whl/pip/_internal/network/session.py", line 175, in user_agent
    setuptools_dist = get_default_environment().get_distribution("setuptools")
                      ^^^^^^^^^^^^^^^^^^^^^^^^^^^^^^^^^^^^^^^^^^^^^^^^^^^^^^^^
  File "/tmp/tmpnlz8l5dq/pip-23.0.1-py3-none-any.whl/pip/_internal/metadata/importlib/_envs.py", line 188, in get_distribution
    return next(matches, None)
           ^^^^^^^^^^^^^^^^^^^
  File "/tmp/tmpnlz8l5dq/pip-23.0.1-py3-none-any.whl/pip/_internal/metadata/importlib/_envs.py", line 183, in <genexpr>
    matches = (
              ^
  File "/tmp/tmpnlz8l5dq/pip-23.0.1-py3-none-any.whl/pip/_internal/metadata/base.py", line 612, in iter_all_distributions
    for dist in self._iter_distributions():
  File "/tmp/tmpnlz8l5dq/pip-23.0.1-py3-none-any.whl/pip/_internal/metadata/importlib/_envs.py", line 176, in _iter_distributions
    for dist in finder.find_eggs(location):
  File "/tmp/tmpnlz8l5dq/pip-23.0.1-py3-none-any.whl/pip/_internal/metadata/importlib/_envs.py", line 146, in find_eggs
    yield from self._find_eggs_in_zip(location)
  File "/tmp/tmpnlz8l5dq/pip-23.0.1-py3-none-any.whl/pip/_internal/metadata/importlib/_envs.py", line 123, in _find_eggs_in_zip
    from pip._vendor.pkg_resources import find_eggs_in_zip
  File "/tmp/tmpnlz8l5dq/pip-23.0.1-py3-none-any.whl/pip/_vendor/pkg_resources/__init__.py", line 3251, in <module>
    @_call_aside
     ^^^^^^^^^^^
  File "/tmp/tmpnlz8l5dq/pip-23.0.1-py3-none-any.whl/pip/_vendor/pkg_resources/__init__.py", line 3235, in _call_aside
    f(*args, **kwargs)
  File "/tmp/tmpnlz8l5dq/pip-23.0.1-py3-none-any.whl/pip/_vendor/pkg_resources/__init__.py", line 3264, in _initialize_master_working_set
    working_set = WorkingSet._build_master()
                  ^^^^^^^^^^^^^^^^^^^^^^^^^^
  File "/tmp/tmpnlz8l5dq/pip-23.0.1-py3-none-any.whl/pip/_vendor/pkg_resources/__init__.py", line 574, in _build_master
    ws = cls()
         ^^^^^
  File "/tmp/tmpnlz8l5dq/pip-23.0.1-py3-none-any.whl/pip/_vendor/pkg_resources/__init__.py", line 567, in __init__
    self.add_entry(entry)
  File "/tmp/tmpnlz8l5dq/pip-23.0.1-py3-none-any.whl/pip/_vendor/pkg_resources/__init__.py", line 623, in add_entry
    for dist in find_distributions(entry, True):
                ^^^^^^^^^^^^^^^^^^^^^^^^^^^^^^^
  File "/tmp/tmpnlz8l5dq/pip-23.0.1-py3-none-any.whl/pip/_vendor/pkg_resources/__init__.py", line 1969, in find_distributions
    importer = get_importer(path_item)
               ^^^^^^^^^^^^^^^^^^^^^^^
  File "/usr/lib/python3.11/pkgutil.py", line 422, in get_importer
    importer = path_hook(path_item)
               ^^^^^^^^^^^^^^^^^^^^
  File "<frozen importlib._bootstrap_external>", line 1698, in path_hook_for_FileFinder
  File "<frozen importlib._bootstrap_external>", line 167, in _path_isdir
FileNotFoundError: [Errno 2] No such file or directory
Traceback (most recent call last):
  File "<frozen runpy>", line 198, in _run_module_as_main
  File "<frozen runpy>", line 88, in _run_code
  File "/usr/lib/python3.11/ensurepip/__main__.py", line 5, in <module>
    sys.exit(ensurepip._main())
             ^^^^^^^^^^^^^^^^^
  File "/usr/lib/python3.11/ensurepip/__init__.py", line 319, in _main
    return _bootstrap(
           ^^^^^^^^^^^
  File "/usr/lib/python3.11/ensurepip/__init__.py", line 235, in _bootstrap
    return _run_pip([*args, *_PACKAGE_NAMES], additional_paths)
           ^^^^^^^^^^^^^^^^^^^^^^^^^^^^^^^^^^^^^^^^^^^^^^^^^^^^
  File "/usr/lib/python3.11/ensurepip/__init__.py", line 131, in _run_pip
    return subprocess.run(cmd, check=True).returncode
           ^^^^^^^^^^^^^^^^^^^^^^^^^^^^^^^
  File "/usr/lib/python3.11/subprocess.py", line 571, in run
    raise CalledProcessError(retcode, process.args,
subprocess.CalledProcessError: Command '['/home/b-michaud/.local/share/pypoetry/venv/bin/python3.11', '-W', 'ignore::DeprecationWarning', '-c', '\nimport runpy\nimport sys\nsys.path = [\'/tmp/tmpnlz8l5dq/pip-23.0.1-py3-none-any.whl\', \'/tmp/tmpnlz8l5dq/setuptools-66.1.1-py3-none-any.whl\'] + sys.path\nsys.argv[1:] = [\'install\', \'--no-cache-dir\', \'--no-index\', \'--find-links\', \'/tmp/tmpnlz8l5dq\', \'--upgrade\', \'setuptools\', \'pip\']\nrunpy.run_module("pip", run_name="__main__", alter_sys=True)\n']' returned non-zero exit status 2.

Traceback:

  File "<stdin>", line 923, in main
  File "<stdin>", line 562, in run
